<?xml version="1.0" encoding="UTF-8"?><testsuite name="nosetests" tests="3" errors="0" failures="1" skip="0"><testcase classname="tests.authentication_tests.StandAloneTests" name="test_login" time="0.001"><failure type="exceptions.AssertionError" message="None is not true&#10;-------------------- &gt;&gt; begin captured stdout &lt;&lt; ---------------------&#10;this line will not be covered by test cases.&#10;this line will not be covered by test cases as well.&#10;&#10;--------------------- &gt;&gt; end captured stdout &lt;&lt; ----------------------"><![CDATA[  File "/usr/lib64/python2.7/unittest/case.py", line 369, in run
    testMethod()
  File "/usr/lib/python2.7/site-packages/mock/mock.py", line 1305, in patched
    return func(*args, **keywargs)
  File "/home/centos/dev/project1/tests/authentication_tests.py", line 29, in test_login
    self.assertTrue(auth.logout())
  File "/usr/lib64/python2.7/unittest/case.py", line 462, in assertTrue
    raise self.failureException(msg)
None is not true
-------------------- >> begin captured stdout << ---------------------
this line will not be covered by test cases.
this line will not be covered by test cases as well.

--------------------- >> end captured stdout << ----------------------]]></failure><system-out><![CDATA[this line will not be covered by test cases.
this line will not be covered by test cases as well.
]]></system-out></testcase><testcase classname="tests.authentication_tests.StandAloneTests" name="test_login_bad_creds" time="0.001"></testcase><testcase classname="tests.authentication_tests.StandAloneTests" name="test_login_error" time="0.000"><system-out><![CDATA[I can't authenticate you.
]]></system-out></testcase></testsuite>